<?xml version="1.0" encoding="utf-8"?>
<!-- This URDF was automatically created by SolidWorks to URDF Exporter! Originally created by Stephen Brawner (brawner@gmail.com) 
     Commit Version: 1.5.1-0-g916b5db  Build Version: 1.5.7152.31018
     For more information, please see http://wiki.ros.org/sw_urdf_exporter -->
<robot
  name="skate_sus_frame">
  <link
    name="base_link">
    <inertial>
      <origin
        xyz="-2.7443E-12 3.9646E-06 0.11505"
        rpy="0 0 0" />
      <mass
        value="23.26" />
      <inertia
        ixx="0.31254"
        ixy="-1.7547E-11"
        ixz="-6.234E-15"
        iyy="0.44265"
        iyz="-1.4289E-14"
        izz="0.68535" />
    </inertial>
    <visual>
      <origin
        xyz="0 0 0"
        rpy="0 0 0" />
      <geometry>
        <mesh
          filename="package://skate_sus_frame/meshes/base_link.STL" />
      </geometry>
      <material
        name="">
        <color
          rgba="0.79216 0.81961 0.93333 1" />
      </material>
    </visual>
    <collision>
      <origin
        xyz="0 0 0"
        rpy="0 0 0" />
      <geometry>
        <mesh
          filename="package://skate_sus_frame/meshes/base_link.STL" />
      </geometry>
    </collision>
  </link>
  <link
    name="LF_wheel">
    <inertial>
      <origin
        xyz="5.7674E-07 -0.035266 1.0788E-06"
        rpy="0 0 0" />
      <mass
        value="3.8843" />
      <inertia
        ixx="0.0093252"
        ixy="1.6431E-07"
        ixz="-3.3977E-08"
        iyy="0.016546"
        iyz="3.2982E-07"
        izz="0.0093251" />
    </inertial>
    <visual>
      <origin
        xyz="0 0 0"
        rpy="0 0 0" />
      <geometry>
        <mesh
          filename="package://skate_sus_frame/meshes/LF_wheel.STL" />
      </geometry>
      <material
        name="">
        <color
          rgba="0.89804 0.91765 0.92941 1" />
      </material>
    </visual>
    <collision>
      <origin
        xyz="0 0 0"
        rpy="0 0 0" />
      <geometry>
        <mesh
          filename="package://skate_sus_frame/meshes/LF_wheel.STL" />
      </geometry>
    
    </collision>

  </link>


  <joint
    name="LF_joint"
    type="continuous">
    <origin
      xyz="0.24182 0.33681 -0.070114"
      rpy="0 0 0" />
    <parent
      link="base_link" />
    <child
      link="LF_wheel" />
    <axis
      xyz="0 -1 0" />
    <limit
      effort="11.12"
      velocity="25.76" />
  </joint>



  <link
    name="LM_wheel">
    <inertial>
      <origin
        xyz="9.4275E-07 -0.035266 7.9606E-07"
        rpy="0 0 0" />
      <mass
        value="3.8843" />
      <inertia
        ixx="0.0093252"
        ixy="2.7582E-07"
        ixz="-4.1995E-08"
        iyy="0.016546"
        iyz="2.4474E-07"
        izz="0.0093252" />
    </inertial>
    <visual>
      <origin
        xyz="0 0 0"
        rpy="0 0 0" />
      <geometry>
        <mesh
          filename="package://skate_sus_frame/meshes/LM_wheel.STL" />
      </geometry>
      <material
        name="">
        <color
          rgba="0.89804 0.91765 0.92941 1" />
      </material>
    </visual>
    <collision>
      <origin
        xyz="0 0 0"
        rpy="0 0 0" />
      <geometry>
        <mesh
          filename="package://skate_sus_frame/meshes/LM_wheel.STL" />
      </geometry>
     
    </collision>
  </link>
  <joint
    name="LM_joint"
    type="continuous">
    <origin
      xyz="0 0.33681 -0.070114"
      rpy="0 0 0" />
    <parent
      link="base_link" />
    <child
      link="LM_wheel" />
    <axis
      xyz="0 -1 0" />
    <limit
      effort="11.12"
      velocity="25.76" />
  </joint>
  <link
    name="LB_wheel">
    <inertial>
      <origin
        xyz="8.698E-07 -0.035266 8.7973E-07"
        rpy="0 0 0" />
      <mass
        value="3.8843" />
      <inertia
        ixx="0.0093252"
        ixy="2.5428E-07"
        ixz="-4.1202E-08"
        iyy="0.016546"
        iyz="2.671E-07"
        izz="0.0093252" />
    </inertial>
    <visual>
      <origin
        xyz="0 0 0"
        rpy="0 0 0" />
      <geometry>
        <mesh
          filename="package://skate_sus_frame/meshes/LB_wheel.STL" />
      </geometry>
      <material
        name="">
        <color
          rgba="0.89804 0.91765 0.92941 1" />
      </material>
    </visual>
    <collision>
      <origin
        xyz="0 0 0"
        rpy="0 0 0" />
      <geometry>
        <mesh
          filename="package://skate_sus_frame/meshes/LB_wheel.STL" />
      </geometry>
     
    </collision>
  </link>
  <joint
    name="LB_joint"
    type="continuous">
    <origin
      xyz="-0.24182 0.33681 -0.070114"
      rpy="0 0 0" />
    <parent
      link="base_link" />
    <child
      link="LB_wheel" />
    <axis
      xyz="0 -1 0" />
    <limit
      effort="11.12"
      velocity="25.76" />
  </joint>
  <link
    name="RF_wheel">
    <inertial>
      <origin
        xyz="9.5919E-07 0.035266 7.8173E-07"
        rpy="0 0 0" />
      <mass
        value="3.8843" />
      <inertia
        ixx="0.0093251"
        ixy="-2.9188E-07"
        ixz="-3.9755E-08"
        iyy="0.016546"
        iyz="-2.2541E-07"
        izz="0.0093252" />
    </inertial>
    <visual>
      <origin
        xyz="0 0 0"
        rpy="0 0 0" />
      <geometry>
        <mesh
          filename="package://skate_sus_frame/meshes/RF_wheel.STL" />
      </geometry>
      <material
        name="">
        <color
          rgba="0.89804 0.91765 0.92941 1" />
      </material>
    </visual>
    <collision>
      <origin
        xyz="0 0 0"
        rpy="0 0 0" />
      <geometry>
        <mesh
          filename="package://skate_sus_frame/meshes/RF_wheel.STL" />
      </geometry>
     
    </collision>
  </link>
  <joint
    name="RF_joint"
    type="continuous">
    <origin
      xyz="0.24182 -0.33671 -0.070114"
      rpy="0 0 0" />
    <parent
      link="base_link" />
    <child
      link="RF_wheel" />
    <axis
      xyz="0 1 0" />
    <limit
      effort="11.12"
      velocity="25.76" />
  </joint>
  <link
    name="RM_wheel">
    <inertial>
      <origin
        xyz="1.1904E-06 0.035266 2.7274E-07"
        rpy="0 0 0" />
      <mass
        value="3.8843" />
      <inertia
        ixx="0.0093251"
        ixy="-3.6103E-07"
        ixz="-1.4108E-08"
        iyy="0.016546"
        iyz="-7.4231E-08"
        izz="0.0093252" />
    </inertial>
    <visual>
      <origin
        xyz="0 0 0"
        rpy="0 0 0" />
      <geometry>
        <mesh
          filename="package://skate_sus_frame/meshes/RM_wheel.STL" />
      </geometry>
      <material
        name="">
        <color
          rgba="0.89804 0.91765 0.92941 1" />
      </material>
    </visual>
    <collision>
      <origin
        xyz="0 0 0"
        rpy="0 0 0" />
      <geometry>
        <mesh
          filename="package://skate_sus_frame/meshes/RM_wheel.STL" />
      </geometry>
     
    </collision>
  </link>
  <joint
    name="RM_joint"
    type="continuous">
    <origin
      xyz="0 -0.33671 -0.070114"
      rpy="0 0 0" />
    <parent
      link="base_link" />
    <child
      link="RM_wheel" />
    <axis
      xyz="0 1 0" />
    <limit
      effort="11.12"
      velocity="25.76" />
  </joint>
  <link
    name="RB_wheel">
    <inertial>
      <origin
        xyz="9.1931E-07 0.035266 8.2826E-07"
        rpy="0 0 0" />
      <mass
        value="3.8843" />
      <inertia
        ixx="0.0093252"
        ixy="-2.8036E-07"
        ixz="-4.0869E-08"
        iyy="0.016546"
        iyz="-2.3958E-07"
        izz="0.0093252" />
    </inertial>
    <visual>
      <origin
        xyz="0 0 0"
        rpy="0 0 0" />
      <geometry>
        <mesh
          filename="package://skate_sus_frame/meshes/RB_wheel.STL" />
      </geometry>
      <material
        name="">
        <color
          rgba="0.89804 0.91765 0.92941 1" />
      </material>
    </visual>
    <collision>
      <origin
        xyz="0 0 0"
        rpy="0 0 0" />
      <geometry>
        <mesh
          filename="package://skate_sus_frame/meshes/RB_wheel.STL" />
      </geometry>
     
    </collision>
  </link>
  <joint
    name="RB_joint"
    type="continuous">
    <origin
      xyz="-0.24182 -0.33681 -0.070114"
      rpy="0 0 0" />
    <parent
      link="base_link" />
    <child
      link="RB_wheel" />
    <axis
      xyz="0 1 0" />
    <limit
      effort="11.12"
      velocity="25.76" />
  </joint>

  <gazebo reference = "LF_wheel">
    
    <mu1>1.0</mu1>
    <mu2>1.0</mu2>
    <!-- <fdir1>1 0 0</fdir1>
    <kp>1000000.0</kp>
    <kd>100.0</kd> -->
    
  </gazebo>

  <gazebo reference = "LM_wheel">
    
    <mu1>1.0</mu1>
    <mu2>1.0</mu2>
    <!-- <fdir1>1 0 0</fdir1>
    <kp>1000000.0</kp>
    <kd>100.0</kd> -->
  </gazebo>

  <gazebo reference = "LB_wheel">
    
    <mu1>1.0</mu1>
    <mu2>1.0</mu2>
    <!-- <fdir1>1 0 0</fdir1>
    <kp>1000000.0</kp>
    <kd>100.0</kd> -->
  </gazebo>

  <gazebo reference = "RF_wheel">
    
    <mu1>1.0</mu1>
    <mu2>1.0</mu2>
    <!-- <fdir1>1 0 0</fdir1>
    <kp>1000000.0</kp>
    <kd>100.0</kd> -->
  </gazebo>

  <gazebo reference = "RM_wheel">
    
    <mu1>1.0</mu1>
    <mu2>1.0</mu2>
    <!-- <fdir1>1 0 0</fdir1>
    <kp>1000000.0</kp>
    <kd>100.0</kd> -->
  </gazebo>

  <gazebo reference = "RB_wheel">
    
    <mu1>1.0</mu1>
    <mu2>1.0</mu2>
    <!-- <fdir1>1 0 0</fdir1>
    <kp>1000000.0</kp>
    <kd>100.0</kd> -->
  </gazebo> 





</robot>