<?xml version="1.0" ?>
<!-- =================================================================================== -->
<!-- |    This document was autogenerated by xacro from /home/park/catkin_ws/src/dp_description/urdf/dp.xacro | -->
<!-- |    EDITING THIS FILE BY HAND IS NOT RECOMMENDED                                 | -->
<!-- =================================================================================== -->
<robot name="dp">
  <material name="silver">
    <color rgba="0.700 0.700 0.700 1.000"/>
  </material>
  <!-- <xacro:include filename="$(find dp_description)/urdf/dp.trans" /> -->
  <gazebo reference="base_link">
    <material>Gazebo/Grey</material>
  </gazebo>
  <gazebo reference="right_frontwheel_1">
    <material>Gazebo/Black</material>
  </gazebo>
  <gazebo reference="left_frontwheel_1">
    <material>Gazebo/Black</material>
  </gazebo>
  <gazebo reference="right_backwheel_1">
    <material>Gazebo/Black</material>
  </gazebo>
  <gazebo reference="left_backwheel_1">
    <material>Gazebo/Black</material>
  </gazebo>
  <gazebo reference="lidar_1">
    <material>Gazebo/Red</material>
  </gazebo>
  <gazebo reference="middle_case_1">
    <material>Gazebo/Red</material>
  </gazebo>
  <gazebo reference="top_case_1">
    <material>Gazebo/White</material>
  </gazebo>
  <gazebo reference="monitor_1">
    <material>Gazebo/Grey</material>
  </gazebo>
  <gazebo reference="realsense256_1">
    <material>Gazebo/Yellow</material>
  </gazebo>
  <gazebo reference="realsense450_1">
    <material>Gazebo/Yellow</material>
  </gazebo>
  <gazebo reference="base_link">
    <mu1>1.0</mu1>
    <mu2>1.0</mu2>
    <selfCollide>true</selfCollide>
    <gravity>true</gravity>
  </gazebo>
  <gazebo reference="right_frontwheel_1">
    <mu1>100</mu1>
    <mu2>100</mu2>
    <selfCollide>true</selfCollide>
  </gazebo>
  <gazebo reference="left_frontwheel_1">
    <mu1>100</mu1>
    <mu2>100</mu2>
    <selfCollide>true</selfCollide>
  </gazebo>
  <gazebo reference="right_backwheel_1">
    <mu1>100</mu1>
    <mu2>100</mu2>
    <selfCollide>true</selfCollide>
  </gazebo>
  <gazebo reference="left_backwheel_1">
    <mu1>100</mu1>
    <mu2>100</mu2>
    <selfCollide>true</selfCollide>
  </gazebo>
  <gazebo reference="lidar_1">
    <mu1>1.0</mu1>
    <mu2>1.0</mu2>
    <selfCollide>true</selfCollide>
  </gazebo>
  <gazebo reference="middle_case_1">
    <mu1>1.0</mu1>
    <mu2>1.0</mu2>
    <selfCollide>true</selfCollide>
  </gazebo>
  <gazebo reference="top_case_1">
    <mu1>1.0</mu1>
    <mu2>1.0</mu2>
    <selfCollide>true</selfCollide>
  </gazebo>
  <gazebo reference="monitor_1">
    <mu1>1.0</mu1>
    <mu2>1.0</mu2>
    <selfCollide>true</selfCollide>
  </gazebo>
  <gazebo reference="realsense256_1">
    <mu1>1.0</mu1>
    <mu2>1.0</mu2>
    <selfCollide>true</selfCollide>
  </gazebo>
  <gazebo reference="realsense450_1">
    <mu1>1.0</mu1>
    <mu2>1.0</mu2>
    <selfCollide>true</selfCollide>
  </gazebo>
  <!--################################## ROS control ##################################-->
  <gazebo>
    <plugin filename="libgazebo_ros_control.so" name="control"/>
  </gazebo>
  <!--################################## Differential Drive ##################################-->
  <gazebo>
    <plugin filename="libgazebo_ros_diff_drive.so" name="differential_drive_controller">
      <!-- Plugin update rate in Hz -->
      <updateRate>20</updateRate>
      <!-- Name of left joint, defaults to `left_joint` -->
      <leftJoint>left_front_rota</leftJoint>
      <!-- Name of right joint, defaults to `right_joint` -->
      <rightJoint>right_front_rota</rightJoint>
      <!-- Name of left joint, defaults to `left_joint` -->
      <leftJoint>left_back_rota</leftJoint>
      <!-- Name of right joint, defaults to `right_joint` -->
      <rightJoint>right_back_rota</rightJoint>
      <!-- Wheel acceleration, in rad/s^2, defaults to 0.0 rad/s^2 -->
      <wheelAcceleration>1.0</wheelAcceleration>
      <!-- Maximum torque which the wheels can produce, in Nm, defaults to 5 Nm -->
      <wheelTorque>20</wheelTorque>
      <!-- Topic to receive geometry_msgs/Twist message commands, defaults to `cmd_vel` -->
      <commandTopic>cmd_vel</commandTopic>
      <!-- Topic to publish nav_msgs/Odometry messages, defaults to `odom` -->
      <odometryTopic>odom</odometryTopic>
      <!-- Odometry frame, defaults to `odom` -->
      <odometryFrame>odom</odometryFrame>
      <!-- Robot frame to calculate odometry from, defaults to `base_footprint` -->
      <robotBaseFrame>base_link</robotBaseFrame>
      <!-- Odometry source, 0 for ENCODER, 1 for WORLD, defaults to WORLD -->
      <odometrySource>1</odometrySource>
      <!-- Set to true to publish transforms for the wheel links, defaults to false -->
      <publishWheelTF>true</publishWheelTF>
      <!-- Set to true to publish transforms for the odometry, defaults to true -->
      <publishOdom>true</publishOdom>
      <!-- Set to true to publish sensor_msgs/JointState on /joint_states for the wheel joints, defaults to false -->
      <publishWheelJointState>true</publishWheelJointState>
      <!-- Set to true to swap right and left wheels, defaults to true -->
      <legacyMode>false</legacyMode>
    </plugin>
  </gazebo>
  <!--################################## GPU Laser Drive ##################################-->
  <gazebo reference="lidar_1">
    <sensor name="rplidar_a1" type="gpu_ray">
      <pose>0 0 0 0 0 0</pose>
      <visualize>true</visualize>
      <update_rate>10</update_rate>
      <ray>
        <scan>
          <horizontal>
            <samples>720</samples>
            <resolution>1</resolution>
            <min_angle>-2.87979</min_angle>
            <max_angle>2.87979</max_angle>
          </horizontal>
        </scan>
        <range>
          <min>0.10</min>
          <max>30.0</max>
          <resolution>0.01</resolution>
        </range>
        <noise>
          <type>gaussian</type>
          <!-- Noise parameters based on published spec for Hokuyo laser
               achieving "+-30mm" accuracy at range < 10m.  A mean of 0.0m and
               stddev of 0.01m will put 99.7% of samples within 0.03m of the true
               reading. -->
          <mean>0.0</mean>
          <stddev>0.01</stddev>
        </noise>
      </ray>
      <plugin filename="libgazebo_ros_gpu_laser.so" name="gazebo_ros_head_hokuyo_controller">
        <topicName>/scan</topicName>
        <frameName>lidar_1</frameName>
      </plugin>
    </sensor>
  </gazebo>
  <link name="base_link">
    <inertial>
      <origin rpy="0 0 0" xyz="0.05101704305235959 -1.0778151042224695e-05 0.17068007655051307"/>
      <mass value="46.82272807242809"/>
      <inertia ixx="0.626679" ixy="0.000944" ixz="-0.030178" iyy="1.899301" iyz="9.3e-05" izz="1.862284"/>
    </inertial>
    <visual>
      <origin rpy="0 0 0" xyz="0 0 0"/>
      <geometry>
        <mesh filename="package://dp_description/meshes/base_link.stl" scale="0.001 0.001 0.001"/>
      </geometry>
      <material name="silver"/>
    </visual>
    <collision>
      <origin rpy="0 0 0" xyz="0 0 0"/>
      <geometry>
        <mesh filename="package://dp_description/meshes/base_link.stl" scale="0.001 0.001 0.001"/>
      </geometry>
    </collision>
  </link>
  <link name="right_frontwheel_1">
    <inertial>
      <origin rpy="0 0 0" xyz="-2.9390397060513607e-09 -0.03503766439501102 -1.5735230796121158e-07"/>
      <mass value="11.136175678001043"/>
      <inertia ixx="0.026909" ixy="0.0" ixz="-0.0" iyy="0.048102" iyz="0.0" izz="0.026909"/>
    </inertial>
    <visual>
      <origin rpy="0 0 0" xyz="0.229463 -0.2296 -0.081394"/>
      <geometry>
        <mesh filename="package://dp_description/meshes/right_frontwheel_1.stl" scale="0.001 0.001 0.001"/>
      </geometry>
      <material name="silver"/>
    </visual>
    <collision>
      <origin rpy="0 0 0" xyz="0.229463 -0.2296 -0.081394"/>
      <geometry>
        <mesh filename="package://dp_description/meshes/right_frontwheel_1.stl" scale="0.001 0.001 0.001"/>
      </geometry>
    </collision>
  </link>
  <link name="left_frontwheel_1">
    <inertial>
      <origin rpy="0 0 0" xyz="-8.846289908936988e-08 0.035037615642317166 -1.4291986839831683e-07"/>
      <mass value="11.136215821603535"/>
      <inertia ixx="0.026909" ixy="-0.0" ixz="-0.0" iyy="0.048102" iyz="0.0" izz="0.026909"/>
    </inertial>
    <visual>
      <origin rpy="0 0 0" xyz="0.229463 0.2296 -0.081394"/>
      <geometry>
        <mesh filename="package://dp_description/meshes/left_frontwheel_1.stl" scale="0.001 0.001 0.001"/>
      </geometry>
      <material name="silver"/>
    </visual>
    <collision>
      <origin rpy="0 0 0" xyz="0.229463 0.2296 -0.081394"/>
      <geometry>
        <mesh filename="package://dp_description/meshes/left_frontwheel_1.stl" scale="0.001 0.001 0.001"/>
      </geometry>
    </collision>
  </link>
  <link name="right_backwheel_1">
    <inertial>
      <origin rpy="0 0 0" xyz="-3.1951071177704904e-07 -0.03503766439501091 -1.7039963265408353e-07"/>
      <mass value="11.136175678000965"/>
      <inertia ixx="0.026909" ixy="0.0" ixz="-0.0" iyy="0.048102" iyz="0.0" izz="0.026909"/>
    </inertial>
    <visual>
      <origin rpy="0 0 0" xyz="-0.263691 -0.2296 -0.081925"/>
      <geometry>
        <mesh filename="package://dp_description/meshes/right_backwheel_1.stl" scale="0.001 0.001 0.001"/>
      </geometry>
      <material name="silver"/>
    </visual>
    <collision>
      <origin rpy="0 0 0" xyz="-0.263691 -0.2296 -0.081925"/>
      <geometry>
        <mesh filename="package://dp_description/meshes/right_backwheel_1.stl" scale="0.001 0.001 0.001"/>
      </geometry>
    </collision>
  </link>
  <link name="left_backwheel_1">
    <inertial>
      <origin rpy="0 0 0" xyz="-4.355953145962488e-07 0.03503761564231722 -1.9212325416684273e-07"/>
      <mass value="11.136215821603576"/>
      <inertia ixx="0.026909" ixy="-0.0" ixz="-0.0" iyy="0.048102" iyz="0.0" izz="0.026909"/>
    </inertial>
    <visual>
      <origin rpy="0 0 0" xyz="-0.263691 0.2296 -0.081925"/>
      <geometry>
        <mesh filename="package://dp_description/meshes/left_backwheel_1.stl" scale="0.001 0.001 0.001"/>
      </geometry>
      <material name="silver"/>
    </visual>
    <collision>
      <origin rpy="0 0 0" xyz="-0.263691 0.2296 -0.081925"/>
      <geometry>
        <mesh filename="package://dp_description/meshes/left_backwheel_1.stl" scale="0.001 0.001 0.001"/>
      </geometry>
    </collision>
  </link>
  <link name="lidar_1">
    <inertial>
      <origin rpy="0 0 0" xyz="-8.193133987088874e-07 1.8657367368123766e-06 0.03608489423123695"/>
      <mass value="4.8206637754823465"/>
      <inertia ixx="0.005355" ixy="-0.0" ixz="-0.0" iyy="0.005358" iyz="0.0" izz="0.006536"/>
    </inertial>
    <visual>
      <origin rpy="0 0 0" xyz="0.157692 -0.0 -0.616539"/>
      <geometry>
        <mesh filename="package://dp_description/meshes/lidar_1.stl" scale="0.001 0.001 0.001"/>
      </geometry>
      <material name="silver"/>
    </visual>
    <collision>
      <origin rpy="0 0 0" xyz="0.157692 -0.0 -0.616539"/>
      <geometry>
        <mesh filename="package://dp_description/meshes/lidar_1.stl" scale="0.001 0.001 0.001"/>
      </geometry>
    </collision>
  </link>
  <link name="middle_case_1">
    <inertial>
      <origin rpy="0 0 0" xyz="0.29072140518707223 -3.337339200083743e-06 0.08729639670679934"/>
      <mass value="15.782733799040091"/>
      <inertia ixx="0.442139" ixy="1.7e-05" ixz="-0.061942" iyy="0.728843" iyz="3e-06" izz="1.099761"/>
    </inertial>
    <visual>
      <origin rpy="0 0 0" xyz="0.258804 0.0 -0.19933"/>
      <geometry>
        <mesh filename="package://dp_description/meshes/middle_case_1.stl" scale="0.001 0.001 0.001"/>
      </geometry>
      <material name="silver"/>
    </visual>
    <collision>
      <origin rpy="0 0 0" xyz="0.258804 0.0 -0.19933"/>
      <geometry>
        <mesh filename="package://dp_description/meshes/middle_case_1.stl" scale="0.001 0.001 0.001"/>
      </geometry>
    </collision>
  </link>
  <link name="top_case_1">
    <inertial>
      <origin rpy="0 0 0" xyz="0.31777165910855737 -7.51698507369497e-05 0.1964836833027458"/>
      <mass value="17.19984458184514"/>
      <inertia ixx="0.418849" ixy="-0.000187" ixz="-0.03852" iyy="0.640039" iyz="4.1e-05" izz="0.811263"/>
    </inertial>
    <visual>
      <origin rpy="0 0 0" xyz="0.281871 0.0 -0.308261"/>
      <geometry>
        <mesh filename="package://dp_description/meshes/top_case_1.stl" scale="0.001 0.001 0.001"/>
      </geometry>
      <material name="silver"/>
    </visual>
    <collision>
      <origin rpy="0 0 0" xyz="0.281871 0.0 -0.308261"/>
      <geometry>
        <mesh filename="package://dp_description/meshes/top_case_1.stl" scale="0.001 0.001 0.001"/>
      </geometry>
    </collision>
  </link>
  <link name="monitor_1">
    <inertial>
      <origin rpy="0 0 0" xyz="0.001655376259088126 0.07749999999833582 0.0002915373902269147"/>
      <mass value="0.33543851271956476"/>
      <inertia ixx="0.000854" ixy="0.0" ixz="3.2e-05" iyy="0.000188" iyz="-0.0" izz="0.000678"/>
    </inertial>
    <visual>
      <origin rpy="0 0 0" xyz="-0.30675 0.0775 -0.474076"/>
      <geometry>
        <mesh filename="package://dp_description/meshes/monitor_1.stl" scale="0.001 0.001 0.001"/>
      </geometry>
      <material name="silver"/>
    </visual>
    <collision>
      <origin rpy="0 0 0" xyz="-0.30675 0.0775 -0.474076"/>
      <geometry>
        <mesh filename="package://dp_description/meshes/monitor_1.stl" scale="0.001 0.001 0.001"/>
      </geometry>
    </collision>
  </link>
  <link name="realsense256_1">
    <inertial>
      <origin rpy="0 0 0" xyz="1.3233874079920938e-07 8.336765847105631e-10 0.010999970214392252"/>
      <mass value="0.09367112401702242"/>
      <inertia ixx="8.9e-05" ixy="-0.0" ixz="0.0" iyy="5e-06" iyz="0.0" izz="8.7e-05"/>
    </inertial>
    <visual>
      <origin rpy="0 0 0" xyz="0.236745 -0.0 -0.467447"/>
      <geometry>
        <mesh filename="package://dp_description/meshes/realsense256_1.stl" scale="0.001 0.001 0.001"/>
      </geometry>
      <material name="silver"/>
    </visual>
    <collision>
      <origin rpy="0 0 0" xyz="0.236745 -0.0 -0.467447"/>
      <geometry>
        <mesh filename="package://dp_description/meshes/realsense256_1.stl" scale="0.001 0.001 0.001"/>
      </geometry>
    </collision>
  </link>
  <link name="realsense450_1">
    <inertial>
      <origin rpy="0 0 0" xyz="0.005500294725026472 -4.3524614181041663e-07 0.00799970592549848"/>
      <mass value="0.037001926351152764"/>
      <inertia ixx="1.9e-05" ixy="-0.0" ixz="0.0" iyy="1e-06" iyz="-0.0" izz="1.9e-05"/>
    </inertial>
    <visual>
      <origin rpy="0 0 0" xyz="0.237702 -4.3e-05 -0.507313"/>
      <geometry>
        <mesh filename="package://dp_description/meshes/realsense450_1.stl" scale="0.001 0.001 0.001"/>
      </geometry>
      <material name="silver"/>
    </visual>
    <collision>
      <origin rpy="0 0 0" xyz="0.237702 -4.3e-05 -0.507313"/>
      <geometry>
        <mesh filename="package://dp_description/meshes/realsense450_1.stl" scale="0.001 0.001 0.001"/>
      </geometry>
    </collision>
  </link>
  <joint name="right_front_rota" type="continuous">
    <origin rpy="0 0 0" xyz="-0.229463 0.2296 0.081394"/>
    <parent link="base_link"/>
    <child link="right_frontwheel_1"/>
    <axis xyz="0.0 1.0 0.0"/>
  </joint>
  <joint name="left_front_rota" type="continuous">
    <origin rpy="0 0 0" xyz="-0.229463 -0.2296 0.081394"/>
    <parent link="base_link"/>
    <child link="left_frontwheel_1"/>
    <axis xyz="-0.0 1.0 0.0"/>
  </joint>
  <joint name="right_back_rota" type="continuous">
    <origin rpy="0 0 0" xyz="0.263691 0.2296 0.081925"/>
    <parent link="base_link"/>
    <child link="right_backwheel_1"/>
    <axis xyz="0.0 1.0 0.0"/>
  </joint>
  <joint name="left_back_rota" type="continuous">
    <origin rpy="0 0 0" xyz="0.263691 -0.2296 0.081925"/>
    <parent link="base_link"/>
    <child link="left_backwheel_1"/>
    <axis xyz="0.0 1.0 0.0"/>
  </joint>
  <joint name="lidar_rota" type="continuous">
    <origin rpy="0 0 0" xyz="-0.157692 0.0 0.616539"/>
    <parent link="base_link"/>
    <child link="lidar_1"/>
    <axis xyz="0.0 -0.0 1.0"/>
  </joint>
  <joint name="middle_base_att" type="fixed">
    <origin rpy="0 0 0" xyz="-0.258804 0.0 0.19933"/>
    <parent link="base_link"/>
    <child link="middle_case_1"/>
  </joint>
  <joint name="top_middle_att" type="fixed">
    <origin rpy="0 0 0" xyz="-0.023067 0.0 0.108931"/>
    <parent link="middle_case_1"/>
    <child link="top_case_1"/>
  </joint>
  <joint name="monitor_att" type="fixed">
    <origin rpy="0 0 0" xyz="0.588621 -0.0775 0.165815"/>
    <parent link="top_case_1"/>
    <child link="monitor_1"/>
  </joint>
  <joint name="realsense256_joint" type="fixed">
    <origin rpy="0 0 0" xyz="0.045126 0.0 0.159186"/>
    <parent link="top_case_1"/>
    <child link="realsense256_1"/>
  </joint>
  <joint name="realsense450_joint" type="fixed">
    <origin rpy="0 0 0" xyz="0.044169 4.3e-05 0.199052"/>
    <parent link="top_case_1"/>
    <child link="realsense450_1"/>
  </joint>
</robot>

